<?xml version='1.0' encoding='utf-8'?>
<robot name="Acebott_Spider_URDF">
    <link name="Body">
        <inertial>
            <origin xyz="-0.09893936727834697 -0.09172392482990159 0.008946823496255288" rpy="0.0 0.0 0.0" />
            <mass value="0.08199535557972024" />
            <inertia ixx="9.49581199758884e-05" iyy="7.208979598154718e-05" izz="0.00012865767930647165" ixy="2.726693653851142e-12" iyz="8.124631609846e-15" ixz="8.776982504503372e-15" />
        </inertial>
        <visual name="Body_visual">
            <origin xyz="0.0 0.0 0.0" rpy="0.0 0.0 0.0" />
            <geometry>
                <mesh filename="meshes/Body.stl" scale="0.001 0.001 0.001" />
            </geometry>
        </visual>
        <collision name="Body_collision">
            <origin xyz="0.0 0.0 0.0" rpy="0.0 0.0 0.0" />
            <geometry>
                <mesh filename="meshes/Body.stl" scale="0.001 0.001 0.001" />
            </geometry>
        </collision>
    </link>
    <link name="Hip_HR">
        <inertial>
            <origin xyz="0.02125000270970605 0.0074247812089937425 0.0032419535209816308" rpy="0.0 -0.0 0.0" />
            <mass value="0.004533521000884564" />
            <inertia ixx="7.034457005123957e-07" iyy="1.1507372874024822e-06" izz="1.15058598772857e-06" ixy="-3.3173718877997107e-07" iyz="-2.51378505530601e-07" ixz="-3.320713292271822e-07" />
        </inertial>
        <visual name="Hip_HR_visual">
            <origin xyz="0.0653393700000001 -0.12967392 0.014191503999999758" rpy="-3.1415926535897913 -0.0 0.0" />
            <geometry>
                <mesh filename="meshes/Hip_HR.stl" scale="0.001 0.001 0.001" />
            </geometry>
        </visual>
        <collision name="Hip_HR_collision">
            <origin xyz="0.0653393700000001 -0.12967392 0.014191503999999758" rpy="-3.1415926535897913 -0.0 0.0" />
            <geometry>
                <mesh filename="meshes/Hip_HR.stl" scale="0.001 0.001 0.001" />
            </geometry>
        </collision>
    </link>
    <link name="Leg_HR">
        <inertial>
            <origin xyz="0.008736659310475159 -0.00034664721693226155 0.015624315795401848" rpy="0.0 -0.0 0.0" />
            <mass value="0.009713411899903171" />
            <inertia ixx="5.98223690582235e-07" iyy="1.976798624633082e-06" izz="1.630611419272467e-06" ixy="2.0516984113919095e-08" iyz="-8.162992944578415e-09" ixz="3.9205420868662616e-08" />
        </inertial>
        <visual name="Leg_HR_visual">
            <origin xyz="0.022839369999999443 0.003491503999999491 0.14135658" rpy="1.5707963267949 -0.0 0.0" />
            <geometry>
                <mesh filename="meshes/Leg_HR.stl" scale="0.001 0.001 0.001" />
            </geometry>
        </visual>
        <collision name="Leg_HR_collision">
            <origin xyz="0.022839369999999443 0.003491503999999491 0.14135658" rpy="1.5707963267949 -0.0 0.0" />
            <geometry>
                <mesh filename="meshes/Leg_HR.stl" scale="0.001 0.001 0.001" />
            </geometry>
        </collision>
    </link>
    <link name="Hip_VL">
        <inertial>
            <origin xyz="-0.021249997290224185 -0.0074247715270273585 0.0032419535209814066" rpy="0.0 -0.0 0.0" />
            <mass value="0.004533521000884648" />
            <inertia ixx="7.034457004552396e-07" iyy="1.1507372874747252e-06" izz="1.15058598786068e-06" ixy="-3.3173718877987646e-07" iyz="2.513785055304499e-07" ixz="3.320713292254234e-07" />
        </inertial>
        <visual name="Hip_VL_visual">
            <origin xyz="0.13253937000000002 -0.0537739199999998 0.014191504000000082" rpy="3.1415926535897922 -0.0 0.0" />
            <geometry>
                <mesh filename="meshes/Hip_VL.stl" scale="0.001 0.001 0.001" />
            </geometry>
        </visual>
        <collision name="Hip_VL_collision">
            <origin xyz="0.13253937000000002 -0.0537739199999998 0.014191504000000082" rpy="3.1415926535897922 -0.0 0.0" />
            <geometry>
                <mesh filename="meshes/Hip_VL.stl" scale="0.001 0.001 0.001" />
            </geometry>
        </collision>
    </link>
    <link name="Leg_VL">
        <inertial>
            <origin xyz="-0.008736653840611055 0.0003466472169322682 0.015624315430607601" rpy="0.0 -0.0 0.0" />
            <mass value="0.009713411899903254" />
            <inertia ixx="5.982236596912551e-07" iyy="1.9767986768641694e-06" izz="1.6306115023945891e-06" ixy="2.051698599421654e-08" iyz="8.162991201413366e-09" ixz="-3.920539899910423e-08" />
        </inertial>
        <visual name="Leg_VL_visual">
            <origin xyz="0.17503937000000122 -0.0034915040000001118 -0.042091269999999695" rpy="-1.5707963267948994 -0.0 0.0" />
            <geometry>
                <mesh filename="meshes/Leg_VL.stl" scale="0.001 0.001 0.001" />
            </geometry>
        </visual>
        <collision name="Leg_VL_collision">
            <origin xyz="0.17503937000000122 -0.0034915040000001118 -0.042091269999999695" rpy="-1.5707963267948994 -0.0 0.0" />
            <geometry>
                <mesh filename="meshes/Leg_VL.stl" scale="0.001 0.001 0.001" />
            </geometry>
        </collision>
    </link>
    <link name="Hip_VR">
        <inertial>
            <origin xyz="0.021264245482194515 -0.007424762173149944 0.003247422353883134" rpy="0.0 -0.0 0.0" />
            <mass value="0.004533497206662651" />
            <inertia ixx="7.037160970528777e-07" iyy="1.1510120554577788e-06" izz="1.1505860402810898e-06" ixy="3.31528390240217e-07" iyz="2.5147873424627667e-07" ixz="-3.3243970524026796e-07" />
        </inertial>
        <visual name="Hip_VR_visual">
            <origin xyz="0.06533937 -0.05377392000000002 0.014199999999999977" rpy="-3.1415926535897927 -0.0 0.0" />
            <geometry>
                <mesh filename="meshes/Hip_VR.stl" scale="0.001 0.001 0.001" />
            </geometry>
        </visual>
        <collision name="Hip_VR_collision">
            <origin xyz="0.06533937 -0.05377392000000002 0.014199999999999977" rpy="-3.1415926535897927 -0.0 0.0" />
            <geometry>
                <mesh filename="meshes/Hip_VR.stl" scale="0.001 0.001 0.001" />
            </geometry>
        </collision>
    </link>
    <link name="Leg_VR">
        <inertial>
            <origin xyz="0.008736659310472834 0.00034665509828700204 0.015624315430609173" rpy="0.0 -0.0 0.0" />
            <mass value="0.009713411899903397" />
            <inertia ixx="5.98223633553072e-07" iyy="1.9767985937420955e-06" izz="1.6306113931343143e-06" ixy="-2.0516677225808784e-08" iyz="8.163047333496193e-09" ixz="3.9205427273677146e-08" />
        </inertial>
        <visual name="Leg_VR_visual">
            <origin xyz="0.022839370000000553 -0.0034914999999996884 -0.04209127000000002" rpy="-1.5707963267948892 -0.0 0.0" />
            <geometry>
                <mesh filename="meshes/Leg_VR.stl" scale="0.001 0.001 0.001" />
            </geometry>
        </visual>
        <collision name="Leg_VR_collision">
            <origin xyz="0.022839370000000553 -0.0034914999999996884 -0.04209127000000002" rpy="-1.5707963267948892 -0.0 0.0" />
            <geometry>
                <mesh filename="meshes/Leg_VR.stl" scale="0.001 0.001 0.001" />
            </geometry>
        </collision>
    </link>
    <link name="Hip_HL">
        <inertial>
            <origin xyz="-0.021268485926847092 0.007424783870094043 0.0032474308446560273" rpy="0.0 -0.0 0.0" />
            <mass value="0.004533502365832292" />
            <inertia ixx="7.037170149500819e-07" iyy="1.1514694098579243e-06" izz="1.1510436407128049e-06" ixy="3.3172085519662725e-07" iyz="-2.514791406501123e-07" ixz="3.325833205591262e-07" />
        </inertial>
        <visual name="Hip_HL_visual">
            <origin xyz="0.13253937000000002 -0.12967392 0.014199999999999956" rpy="-3.141592653589793 -0.0 0.0" />
            <geometry>
                <mesh filename="meshes/Hip_HL.stl" scale="0.001 0.001 0.001" />
            </geometry>
        </visual>
        <collision name="Hip_HL_collision">
            <origin xyz="0.13253937000000002 -0.12967392 0.014199999999999956" rpy="-3.141592653589793 -0.0 0.0" />
            <geometry>
                <mesh filename="meshes/Hip_HL.stl" scale="0.001 0.001 0.001" />
            </geometry>
        </collision>
    </link>
    <link name="Leg_HL">
        <inertial>
            <origin xyz="-0.008736656485766013 -0.0003466550982874311 0.015624315795401831" rpy="0.0 -0.0 0.0" />
            <mass value="0.009713411899903402" />
            <inertia ixx="5.982236644441535e-07" iyy="1.976798707766209e-06" izz="1.6306114762672662e-06" ixy="-2.0516679106194272e-08" iyz="-8.163049076679687e-09" ixz="-3.92054824680009e-08" />
        </inertial>
        <visual name="Leg_HL_visual">
            <origin xyz="0.1750512399999999 0.0034914999999906718 0.14135658000000023" rpy="1.5707963267949625 -0.0 0.0" />
            <geometry>
                <mesh filename="meshes/Leg_HL.stl" scale="0.001 0.001 0.001" />
            </geometry>
        </visual>
        <collision name="Leg_HL_collision">
            <origin xyz="0.1750512399999999 0.0034914999999906718 0.14135658000000023" rpy="1.5707963267949625 -0.0 0.0" />
            <geometry>
                <mesh filename="meshes/Leg_HL.stl" scale="0.001 0.001 0.001" />
            </geometry>
        </collision>
    </link>
    <joint name="Body_Hip_HL" type="revolute">
        <origin xyz="-0.13253937000000002 -0.12967392 0.014199999999999999" rpy="3.141592653589793 -0.0 0.0" />
        <parent link="Body" />
        <child link="Hip_HL" />
        <axis xyz="0.0 -3.43908929112419e-16 1.0" />
        <limit lower="-0.872665" upper="0.872665" effort="1000000" velocity="1000000" />
    </joint>
    <joint name="Hip_HL_Leg_HL" type="revolute">
        <origin xyz="-0.04251186999999998 0.011682659999999992 0.010708500000000003" rpy="1.570796326794831 -0.0 0.0" />
        <parent link="Hip_HL" />
        <child link="Leg_HL" />
        <axis xyz="0.0 -6.59928123750708e-14 1.0" />
        <limit lower="-1.570796" upper="0.0" effort="1000000" velocity="1000000" />
    </joint>
    <joint name="Body_Hip_VL" type="revolute">
        <origin xyz="-0.13253937000000002 -0.05377392 0.014199999999999999" rpy="3.1415926535897927 -0.0 0.0" />
        <parent link="Body" />
        <child link="Hip_VL" />
        <axis xyz="-0.0 -4.21198963906871e-16 1.0" />
        <limit lower="-0.872665" upper="0.872665" effort="1000000" velocity="1000000" />
    </joint>
    <joint name="Hip_VL_Leg_VL" type="revolute">
        <origin xyz="-0.0425 -0.011682650000000017 0.010699999999999994" rpy="-1.5707963267948861 -0.0 0.0" />
        <parent link="Hip_VL" />
        <child link="Leg_VL" />
        <axis xyz="-0.0 1.007645192987434e-14 1.0" />
        <limit lower="-0.0" upper="1.570796" effort="1000000" velocity="1000000" />
    </joint>
    <joint name="Body_Hip_VR" type="revolute">
        <origin xyz="-0.06533937 -0.05377392 0.014199999999999999" rpy="3.1415926535897927 -0.0 0.0" />
        <parent link="Body" />
        <child link="Hip_VR" />
        <axis xyz="-0.0 -4.06769447268998e-16 1.0" />
        <limit lower="-0.872665" upper="0.872665" effort="1000000" velocity="1000000" />
    </joint>
    <joint name="Hip_VR_Leg_VR" type="revolute">
        <origin xyz="0.0425 -0.011682650000000017 0.010708499999999994" rpy="-1.5707963267949037 -0.0 0.0" />
        <parent link="Hip_VR" />
        <child link="Leg_VR" />
        <axis xyz="0.0 -7.41533677581482e-15 1.0" />
        <limit lower="-1.570796" upper="0.0" effort="1000000" velocity="1000000" />
    </joint>
    <joint name="Body_Hip_HR" type="revolute">
        <origin xyz="-0.06533937 -0.12967392 0.014199999999999999" rpy="3.141592653589793 -0.0 0.0" />
        <parent link="Body" />
        <child link="Hip_HR" />
        <axis xyz="0.0 -3.43908929112402e-16 1.0" />
        <limit lower="-0.872665" upper="0.872665" effort="1000000" velocity="1000000" />
    </joint>
    <joint name="Hip_HR_Leg_HR" type="revolute">
        <origin xyz="0.0425 0.011682659999999992 0.010700000000000003" rpy="1.5707963267948861 -0.0 0.0" />
        <parent link="Hip_HR" />
        <child link="Leg_HR" />
        <axis xyz="0.0 -1.0841559822893527e-14 1.0" />
        <limit lower="0.0" upper="1.570796" effort="1000000" velocity="1000000" />
    </joint>
</robot>